2019-04-12 23:19:56,820 ERROR: Exception on /api/request/ [POST] [in /Users/dmitrii/one_click/venv/lib/python3.6/site-packages/flask/app.py:1761]
Traceback (most recent call last):
  File "/Users/dmitrii/one_click/venv/lib/python3.6/site-packages/sqlalchemy/engine/base.py", line 1182, in _execute_context
    context)
  File "/Users/dmitrii/one_click/venv/lib/python3.6/site-packages/sqlalchemy/engine/default.py", line 470, in do_execute
    cursor.execute(statement, parameters)
psycopg2.IntegrityError: insert or update on table "requests" violates foreign key constraint "service"
DETAIL:  Key (id)=(21) is not present in table "services_type".


The above exception was the direct cause of the following exception:

Traceback (most recent call last):
  File "/Users/dmitrii/one_click/venv/lib/python3.6/site-packages/flask/app.py", line 2292, in wsgi_app
    response = self.full_dispatch_request()
  File "/Users/dmitrii/one_click/venv/lib/python3.6/site-packages/flask/app.py", line 1815, in full_dispatch_request
    rv = self.handle_user_exception(e)
  File "/Users/dmitrii/one_click/venv/lib/python3.6/site-packages/flask/app.py", line 1718, in handle_user_exception
    reraise(exc_type, exc_value, tb)
  File "/Users/dmitrii/one_click/venv/lib/python3.6/site-packages/flask/_compat.py", line 35, in reraise
    raise value
  File "/Users/dmitrii/one_click/venv/lib/python3.6/site-packages/flask/app.py", line 1813, in full_dispatch_request
    rv = self.dispatch_request()
  File "/Users/dmitrii/one_click/venv/lib/python3.6/site-packages/flask/app.py", line 1799, in dispatch_request
    return self.view_functions[rule.endpoint](**req.view_args)
  File "/Users/dmitrii/one_click/app/api/api.py", line 48, in request_create
    Request.create(description, service_id)
  File "/Users/dmitrii/one_click/app/models.py", line 176, in create
    db.session.commit()
  File "/Users/dmitrii/one_click/venv/lib/python3.6/site-packages/sqlalchemy/orm/scoping.py", line 157, in do
    return getattr(self.registry(), name)(*args, **kwargs)
  File "/Users/dmitrii/one_click/venv/lib/python3.6/site-packages/sqlalchemy/orm/session.py", line 906, in commit
    self.transaction.commit()
  File "/Users/dmitrii/one_click/venv/lib/python3.6/site-packages/sqlalchemy/orm/session.py", line 461, in commit
    self._prepare_impl()
  File "/Users/dmitrii/one_click/venv/lib/python3.6/site-packages/sqlalchemy/orm/session.py", line 441, in _prepare_impl
    self.session.flush()
  File "/Users/dmitrii/one_click/venv/lib/python3.6/site-packages/sqlalchemy/orm/session.py", line 2177, in flush
    self._flush(objects)
  File "/Users/dmitrii/one_click/venv/lib/python3.6/site-packages/sqlalchemy/orm/session.py", line 2297, in _flush
    transaction.rollback(_capture_exception=True)
  File "/Users/dmitrii/one_click/venv/lib/python3.6/site-packages/sqlalchemy/util/langhelpers.py", line 66, in __exit__
    compat.reraise(exc_type, exc_value, exc_tb)
  File "/Users/dmitrii/one_click/venv/lib/python3.6/site-packages/sqlalchemy/util/compat.py", line 187, in reraise
    raise value
  File "/Users/dmitrii/one_click/venv/lib/python3.6/site-packages/sqlalchemy/orm/session.py", line 2261, in _flush
    flush_context.execute()
  File "/Users/dmitrii/one_click/venv/lib/python3.6/site-packages/sqlalchemy/orm/unitofwork.py", line 389, in execute
    rec.execute(self)
  File "/Users/dmitrii/one_click/venv/lib/python3.6/site-packages/sqlalchemy/orm/unitofwork.py", line 548, in execute
    uow
  File "/Users/dmitrii/one_click/venv/lib/python3.6/site-packages/sqlalchemy/orm/persistence.py", line 181, in save_obj
    mapper, table, insert)
  File "/Users/dmitrii/one_click/venv/lib/python3.6/site-packages/sqlalchemy/orm/persistence.py", line 835, in _emit_insert_statements
    execute(statement, params)
  File "/Users/dmitrii/one_click/venv/lib/python3.6/site-packages/sqlalchemy/engine/base.py", line 945, in execute
    return meth(self, multiparams, params)
  File "/Users/dmitrii/one_click/venv/lib/python3.6/site-packages/sqlalchemy/sql/elements.py", line 263, in _execute_on_connection
    return connection._execute_clauseelement(self, multiparams, params)
  File "/Users/dmitrii/one_click/venv/lib/python3.6/site-packages/sqlalchemy/engine/base.py", line 1053, in _execute_clauseelement
    compiled_sql, distilled_params
  File "/Users/dmitrii/one_click/venv/lib/python3.6/site-packages/sqlalchemy/engine/base.py", line 1189, in _execute_context
    context)
  File "/Users/dmitrii/one_click/venv/lib/python3.6/site-packages/sqlalchemy/engine/base.py", line 1402, in _handle_dbapi_exception
    exc_info
  File "/Users/dmitrii/one_click/venv/lib/python3.6/site-packages/sqlalchemy/util/compat.py", line 203, in raise_from_cause
    reraise(type(exception), exception, tb=exc_tb, cause=cause)
  File "/Users/dmitrii/one_click/venv/lib/python3.6/site-packages/sqlalchemy/util/compat.py", line 186, in reraise
    raise value.with_traceback(tb)
  File "/Users/dmitrii/one_click/venv/lib/python3.6/site-packages/sqlalchemy/engine/base.py", line 1182, in _execute_context
    context)
  File "/Users/dmitrii/one_click/venv/lib/python3.6/site-packages/sqlalchemy/engine/default.py", line 470, in do_execute
    cursor.execute(statement, parameters)
sqlalchemy.exc.IntegrityError: (psycopg2.IntegrityError) insert or update on table "requests" violates foreign key constraint "service"
DETAIL:  Key (id)=(21) is not present in table "services_type".
 [SQL: 'INSERT INTO requests (description, date_create, user_id, status_id, service_id) VALUES (%(description)s, %(date_create)s, %(user_id)s, %(status_id)s, %(service_id)s) RETURNING requests.id'] [parameters: {'description': '1', 'date_create': datetime.datetime(2019, 4, 12, 23, 19, 56, 794173), 'user_id': None, 'status_id': 1, 'service_id': '3'}]
2019-04-12 23:38:25,926 INFO: x5 startup [in /Users/dmitrii/one_click/app/__init__.py:60]
2019-04-12 23:39:53,128 INFO: x5 startup [in /Users/dmitrii/one_click/app/__init__.py:61]
