2019-04-12 18:32:55,529 ERROR: Exception on /api/city/ [GET] [in /Users/dmitrii/one_click/venv/lib/python3.6/site-packages/flask/app.py:1761]
Traceback (most recent call last):
  File "/Users/dmitrii/one_click/venv/lib/python3.6/site-packages/sqlalchemy/pool.py", line 1122, in _do_get
    return self._pool.get(wait, self._timeout)
  File "/Users/dmitrii/one_click/venv/lib/python3.6/site-packages/sqlalchemy/util/queue.py", line 145, in get
    raise Empty
sqlalchemy.util.queue.Empty

During handling of the above exception, another exception occurred:

Traceback (most recent call last):
  File "/Users/dmitrii/one_click/venv/lib/python3.6/site-packages/sqlalchemy/engine/base.py", line 2147, in _wrap_pool_connect
    return fn()
  File "/Users/dmitrii/one_click/venv/lib/python3.6/site-packages/sqlalchemy/pool.py", line 387, in connect
    return _ConnectionFairy._checkout(self)
  File "/Users/dmitrii/one_click/venv/lib/python3.6/site-packages/sqlalchemy/pool.py", line 766, in _checkout
    fairy = _ConnectionRecord.checkout(pool)
  File "/Users/dmitrii/one_click/venv/lib/python3.6/site-packages/sqlalchemy/pool.py", line 516, in checkout
    rec = pool._do_get()
  File "/Users/dmitrii/one_click/venv/lib/python3.6/site-packages/sqlalchemy/pool.py", line 1138, in _do_get
    self._dec_overflow()
  File "/Users/dmitrii/one_click/venv/lib/python3.6/site-packages/sqlalchemy/util/langhelpers.py", line 66, in __exit__
    compat.reraise(exc_type, exc_value, exc_tb)
  File "/Users/dmitrii/one_click/venv/lib/python3.6/site-packages/sqlalchemy/util/compat.py", line 187, in reraise
    raise value
  File "/Users/dmitrii/one_click/venv/lib/python3.6/site-packages/sqlalchemy/pool.py", line 1135, in _do_get
    return self._create_connection()
  File "/Users/dmitrii/one_click/venv/lib/python3.6/site-packages/sqlalchemy/pool.py", line 333, in _create_connection
    return _ConnectionRecord(self)
  File "/Users/dmitrii/one_click/venv/lib/python3.6/site-packages/sqlalchemy/pool.py", line 461, in __init__
    self.__connect(first_connect_check=True)
  File "/Users/dmitrii/one_click/venv/lib/python3.6/site-packages/sqlalchemy/pool.py", line 651, in __connect
    connection = pool._invoke_creator(self)
  File "/Users/dmitrii/one_click/venv/lib/python3.6/site-packages/sqlalchemy/engine/strategies.py", line 105, in connect
    return dialect.connect(*cargs, **cparams)
  File "/Users/dmitrii/one_click/venv/lib/python3.6/site-packages/sqlalchemy/engine/default.py", line 393, in connect
    return self.dbapi.connect(*cargs, **cparams)
  File "/Users/dmitrii/one_click/venv/lib/python3.6/site-packages/psycopg2/__init__.py", line 130, in connect
    conn = _connect(dsn, connection_factory=connection_factory, **kwasync)
psycopg2.OperationalError: FATAL:  database "one_click_sevice" does not exist


The above exception was the direct cause of the following exception:

Traceback (most recent call last):
  File "/Users/dmitrii/one_click/venv/lib/python3.6/site-packages/flask/app.py", line 2292, in wsgi_app
    response = self.full_dispatch_request()
  File "/Users/dmitrii/one_click/venv/lib/python3.6/site-packages/flask/app.py", line 1815, in full_dispatch_request
    rv = self.handle_user_exception(e)
  File "/Users/dmitrii/one_click/venv/lib/python3.6/site-packages/flask/app.py", line 1718, in handle_user_exception
    reraise(exc_type, exc_value, tb)
  File "/Users/dmitrii/one_click/venv/lib/python3.6/site-packages/flask/_compat.py", line 35, in reraise
    raise value
  File "/Users/dmitrii/one_click/venv/lib/python3.6/site-packages/flask/app.py", line 1813, in full_dispatch_request
    rv = self.dispatch_request()
  File "/Users/dmitrii/one_click/venv/lib/python3.6/site-packages/flask/app.py", line 1799, in dispatch_request
    return self.view_functions[rule.endpoint](**req.view_args)
  File "/Users/dmitrii/one_click/app/api/api.py", line 10, in city_all
    cities = City.all()
  File "/Users/dmitrii/one_click/app/models.py", line 43, in all
    city = cls.query.all()
  File "/Users/dmitrii/one_click/venv/lib/python3.6/site-packages/sqlalchemy/orm/query.py", line 2703, in all
    return list(self)
  File "/Users/dmitrii/one_click/venv/lib/python3.6/site-packages/sqlalchemy/orm/query.py", line 2855, in __iter__
    return self._execute_and_instances(context)
  File "/Users/dmitrii/one_click/venv/lib/python3.6/site-packages/sqlalchemy/orm/query.py", line 2876, in _execute_and_instances
    close_with_result=True)
  File "/Users/dmitrii/one_click/venv/lib/python3.6/site-packages/sqlalchemy/orm/query.py", line 2885, in _get_bind_args
    **kw
  File "/Users/dmitrii/one_click/venv/lib/python3.6/site-packages/sqlalchemy/orm/query.py", line 2867, in _connection_from_session
    conn = self.session.connection(**kw)
  File "/Users/dmitrii/one_click/venv/lib/python3.6/site-packages/sqlalchemy/orm/session.py", line 998, in connection
    execution_options=execution_options)
  File "/Users/dmitrii/one_click/venv/lib/python3.6/site-packages/sqlalchemy/orm/session.py", line 1003, in _connection_for_bind
    engine, execution_options)
  File "/Users/dmitrii/one_click/venv/lib/python3.6/site-packages/sqlalchemy/orm/session.py", line 403, in _connection_for_bind
    conn = bind.contextual_connect()
  File "/Users/dmitrii/one_click/venv/lib/python3.6/site-packages/sqlalchemy/engine/base.py", line 2112, in contextual_connect
    self._wrap_pool_connect(self.pool.connect, None),
  File "/Users/dmitrii/one_click/venv/lib/python3.6/site-packages/sqlalchemy/engine/base.py", line 2151, in _wrap_pool_connect
    e, dialect, self)
  File "/Users/dmitrii/one_click/venv/lib/python3.6/site-packages/sqlalchemy/engine/base.py", line 1465, in _handle_dbapi_exception_noconnection
    exc_info
  File "/Users/dmitrii/one_click/venv/lib/python3.6/site-packages/sqlalchemy/util/compat.py", line 203, in raise_from_cause
    reraise(type(exception), exception, tb=exc_tb, cause=cause)
  File "/Users/dmitrii/one_click/venv/lib/python3.6/site-packages/sqlalchemy/util/compat.py", line 186, in reraise
    raise value.with_traceback(tb)
  File "/Users/dmitrii/one_click/venv/lib/python3.6/site-packages/sqlalchemy/engine/base.py", line 2147, in _wrap_pool_connect
    return fn()
  File "/Users/dmitrii/one_click/venv/lib/python3.6/site-packages/sqlalchemy/pool.py", line 387, in connect
    return _ConnectionFairy._checkout(self)
  File "/Users/dmitrii/one_click/venv/lib/python3.6/site-packages/sqlalchemy/pool.py", line 766, in _checkout
    fairy = _ConnectionRecord.checkout(pool)
  File "/Users/dmitrii/one_click/venv/lib/python3.6/site-packages/sqlalchemy/pool.py", line 516, in checkout
    rec = pool._do_get()
  File "/Users/dmitrii/one_click/venv/lib/python3.6/site-packages/sqlalchemy/pool.py", line 1138, in _do_get
    self._dec_overflow()
  File "/Users/dmitrii/one_click/venv/lib/python3.6/site-packages/sqlalchemy/util/langhelpers.py", line 66, in __exit__
    compat.reraise(exc_type, exc_value, exc_tb)
  File "/Users/dmitrii/one_click/venv/lib/python3.6/site-packages/sqlalchemy/util/compat.py", line 187, in reraise
    raise value
  File "/Users/dmitrii/one_click/venv/lib/python3.6/site-packages/sqlalchemy/pool.py", line 1135, in _do_get
    return self._create_connection()
  File "/Users/dmitrii/one_click/venv/lib/python3.6/site-packages/sqlalchemy/pool.py", line 333, in _create_connection
    return _ConnectionRecord(self)
  File "/Users/dmitrii/one_click/venv/lib/python3.6/site-packages/sqlalchemy/pool.py", line 461, in __init__
    self.__connect(first_connect_check=True)
  File "/Users/dmitrii/one_click/venv/lib/python3.6/site-packages/sqlalchemy/pool.py", line 651, in __connect
    connection = pool._invoke_creator(self)
  File "/Users/dmitrii/one_click/venv/lib/python3.6/site-packages/sqlalchemy/engine/strategies.py", line 105, in connect
    return dialect.connect(*cargs, **cparams)
  File "/Users/dmitrii/one_click/venv/lib/python3.6/site-packages/sqlalchemy/engine/default.py", line 393, in connect
    return self.dbapi.connect(*cargs, **cparams)
  File "/Users/dmitrii/one_click/venv/lib/python3.6/site-packages/psycopg2/__init__.py", line 130, in connect
    conn = _connect(dsn, connection_factory=connection_factory, **kwasync)
sqlalchemy.exc.OperationalError: (psycopg2.OperationalError) FATAL:  database "one_click_sevice" does not exist

